Workbook
Name __xlnm._FilterDatabase: #N/A
Name __xlnm._FilterDatabase: #N/A
Name __xlnm._FilterDatabase: #N/A
Name __xlnm._FilterDatabase: #N/A
Name __xlnm._FilterDatabase: #N/A
Name __xlnm._FilterDatabase: #N/A
Name __xlnm._FilterDatabase: #N/A
Name __xlnm._FilterDatabase: #N/A
Name __xlnm.Print_Area: 'X-1'!$A$1:$Z$63
Name __xlnm.Print_Area: 'X-2'!$A$1:$Z$63
Name __xlnm.Print_Area: 'X-3'!$A$1:$Z$63
Name __xlnm.Print_Area: 'X-4'!$A$1:$Z$66
Name __xlnm.Print_Area: 'X-5'!$A$1:$Z$64
Name __xlnm.Print_Area: 'X-6'!$A$1:$Z$65
Name __xlnm.Print_Area: 'X-7'!$A$1:$Z$62
Name __xlnm.Print_Area: 'X-8'!$A$1:$AA$62

Sheet X-1
A14: DAFTAR HADIR
A15: TAHUN PELAJARAN 2025/ 2026
M17: Kelas | Q17: : X - 1
A18: KEGIATAN : ................................................................... | M18: Wali Kelas | Q18: : ISMIARTI ARIANI, S. T.
A20: No Urut | B20: No Induk | C20: Nama | D20: L/P | E20: NILAI | U20: KETERANGAN
E23: 1 | F23: 2 | G23: 3 | H23: 4 | I23: 5 | J23: 6 | K23: 7 | L23: 8 | M23: 9 | N23: 10 | O23: 11 | P23: 12 | Q23: 13 | R23: 14 | S23: 15 | T23: 16
A24: 1 | B24: 12206 | C24: ABID LUHUNG FITRA WIYONO | D24: L | E24: 1 | P24: 1 | T24: 1 | U24: 1
A25: 2 | B25: 12217 | C25: ALGIS QIANDRA YUDHA PRATAMA | D25: L | P25: 1 | T25: 1 | U25: 1
A26: 3 | B26: 12222 | C26: ALVIAN RADITYA PRATAMA | D26: L | P26: 1 | T26: 1 | U26: 1
A27: 4 | B27: 12242 | C27: ARSENDI ZIKRI UTOMO PUTRA | D27: L | P27: 1 | T27: 1 | U27: 1
A28: 5 | B28: 12245 | C28: ASKA FATAH FEDORA ILAHI | D28: L | P28: 1 | T28: 1 | U28: 1
A29: 6 | B29: 12255 | C29: BAIQ NINDI REGINA PUTRI | D29: P | P29: 1 | T29: 1 | U29: 1
A30: 7 | B30: 12256 | C30: BERYL AFFAN AFLAHURROJI | D30: L | P30: 1 | T30: 1 | U30: 1
A31: 8 | B31: 12261 | C31: BRILIAN RAFA RAMADAN | D31: L | P31: 1 | T31: 1 | U31: 1
A32: 9 | B32: 12266 | C32: CHANTIKA INTANIA NURMAWATI BASKORO | D32: P | P32: 1 | T32: 1 | U32: 1
A33: 10 | B33: 12268 | C33: DAFFA RAQILLA SUGIONO | D33: L | P33: 1 | T33: 1 | U33: 1
A34: 11 | B34: 12272 | C34: DAVID MAULANA CHAMID | D34: L | P34: 1 | T34: 1 | U34: 1
A35: 12 | B35: 12282 | C35: FADHIL AFFANDI FAYYADH | D35: L | P35: 1 | T35: 1 | U35: 1
A36: 13 | B36: 12296 | C36: GHANI KHAENU RAFA AR RASYID | D36: L | P36: 1 | T36: 1 | U36: 1
... A44: 21 | B44: 12356 | C44: MUHAMMAD ADILA VARIAN KASHIRA | D44: L | P44: 1 | T44: 1 | U44: 1
A45: 22 | B45: 12360 | C45: MUHAMMAD ARKANA AEROFA RUBY | D45: L | U45: 1
A46: 23 | B46: 12363 | C46: MUHAMMAD FADHIL ADIYAKSA | D46: L | U46: 1
A47: 24 | B47: 12373 | C47: MUHAMMAD RAFI AZHAR | D47: L | U47: 1
A48: 25 | B48: 12385 | C48: NADYA NUR CHAIRANI | D48: P
A49: 26 | B49: 12410 | C49: PUTRI SUKE RAMADANI | D49: P
A50: 27 | B50: 12417 | C50: RAFFI ZAAHIR RAMADHAN | D50: L | P50: 1 | T50: 1
A51: 28 | B51: 12426 | C51: RENATA AZALIA NADHIF | D51: P
A52: 29 | B52: 12431 | C52: RIDHANA AGNESIA SUBEKTI | D52: P
A53: 30 | B53: 12438 | C53: RYNESAN VIDYADHIGUNA KURNIA TSABIT | D53: L
A54: 31 | B54: 12453 | C54: SULTAN BARA NUZULUS SYIFA' | D54: L
A55: 32 | B55: 12460 | C55: VALENTIA MAURIS | D55: P
A56: 33 | B56: 12469 | C56: ZIDDANE ASYKURA RAHMAN | D56: L
C57: JUMLAH SISWA LAKI-LAKI | D57: =COUNTIF(D24:D56,"L") -> 22
C58: JUMLAH SISWA PEREMPUAN | D58: =COUNTIF(D24:D56,"P") -> 11
C59: JUMLAH KESELURUHAN | D59: =SUM(D57:D58) -> 33
C60: JML

Sheet X-2
A14: DAFTAR HADIR
A15: TAHUN PELAJARAN 2025/ 2026
M17: Kelas | Q17: : X - 2
A18: KEGIATAN : .................................................................. | M18: Wali Kelas | Q18: : MOH. MUSTANGIN, S. Pd.
A20: No Urut | B20: No Induk | C20: Nama | D20: L/P | E20: NILAI | U20: KETERANGAN
E23: 1 | F23: 2 | G23: 3 | H23: 4 | I23: 5 | J23: 6 | K23: 7 | L23: 8 | M23: 9 | N23: 10 | O23: 11 | P23: 12 | Q23: 13 | R23: 14 | S23: 15 | T23: 16
A24: 1 | B24: 12209 | C24: ADIYAT TAUFANI PUTRA GHANIAN | D24: L | E24: 1 | P24: 1 | T24: 1 | U24: 1
A25: 2 | B25: 12223 | C25: ALVINO SATRIA PUTRA JATMIKO | D25: L | P25: 1 | T25: 1 | U25: 1
A26: 3 | B26: 12237 | C26: ARIA FALIHA ABYDZA | D26: L | P26: 1 | T26: 1 | U26: 1
A27: 4 | B27: 12239 | C27: ARRAFI FAJRI MUHARRAM | D27: L | P27: 1 | T27: 1 | U27: 1
A28: 5 | B28: 12244 | C28: ARYA SATYA DIWANTOKO | D28: L | P28: 1 | T28: 1 | U28: 1
A29: 6 | B29: 12257 | C29: BIANKA AMANISA | D29: P | P29: 1 | T29: 1 | U29: 1
A30: 7 | B30: 12275 | C30: DHIMAS BAYU PRAWIRO WIBISONO | D30: L
A31: 8 | B31: 12292 | C31: FENI ADELIA | D31: P
A32: 9 | B32: 12298 | C32: GIGIH RESTU PANGLIPUR | D32: P
A33: 10 | B33: 12304 | C33: HASYA NAZIFA ADANI | D33: P
A34: 11 | B34: 12312 | C34: IQSYAMAMUDA | D34: L
A35: 12 | B35: 12327 | C35: KENZIE WIRASENA MUHAMMAD AKHTIARY | D35: L
A36: 13 | B36: 12332 | C36: KHENZA PERMATA UNGU | D36: P
A37: 14 | B37: 12338 | C37: LINTANG WISNU PUTRI WIYONO | D37: P
A38: 15 | B38: 12362 | C38: MUHAMMAD DARWIS PUTRA HARIANSYAH | D38: L
A39: 16 | B39: 12364 | C39: MUHAMMAD FAIZ NAUFAL SANTIKA | D39: L
A40: 17 | B40: 12368 | C40: MUHAMMAD JIBRIL ARIE PAMESTI | D40: L | P40: 1 | T40: 1 | U40: 1
A41: 18 | B41: 12375 | C41: MUHAMMAD RASYIDAN KURNIAWAN | D41: L | P41: 1 | T41: 1 | U41: 1
A42: 19 | B42: 12383 | C42: NADHIR NAYAKA NIBRAS PENAMBIH | D42: L | P42: 1 | T42: 1 | U42: 1
A43: 20 | B43: 12390 | C43: NAUFAL ACHMAD SAABIQ | D43: L | P43: 1 | T43: 1 | U43: 1
A44: 21 | B44: 12393 | C44: NAUFAL RAFA ADITYA | D44: L | P44: 1 | T44: 1 | U44: 1
A45: 22 | B45: 12408 | C45: PUTRI NAIRASWARI | D45: P | P45: 1 | T45: 1 | U45: 1
A46: 23 | B46: 12412 | C46: QUEENZY BUEGY LUVRELCIA | D46: P | P46: 1 | T46: 1 | U46: 1
A47: 24 | B47: 12424 | C47: RASYA SERIO ARRAFI | D47: L | P47: 1 | T47: 1 | U47: 1
A48: 25 | B48: 12427 | C48: RENO FEBRIANSYAH | D48: L | P48: 1 | T48: 1 | U48: 1
A49: 26 | B49: 12433 | C49: RISKY ALFIAN MA'RUF | D49: L
A50: 27 | B50: 12436 | C50: RIZKY JELANG RAMADHAN | D50: L | P50: 1 | T50: 1 | U50: 1
A51: 28 | B51: 12447 | C51: SHABRINA FATIMATUS KEY ZAHRA | D51: P | U51: 1
A52: 29 | B52: 12451 | C52: SHERILLA AURA FERNANDA | D52: P
A53: 30 | B53: 12457 | C53: TAHRIZI PASTIKA KURNIAWAN | D53: L
A54: 31 | B54: 12459 | C54: THALITA ARTANTI | D54: P
A55: 32 | B55: 12463 | C55: WALID AL QODHI | D55: L
A56: 33 | B56: 12465 | C56: WIZARD WISNU WARDHANA | D56: L | P56: 1 | T56: 1
A57: 34 | B57: 12471 | C57: ZIZI ARETA MACHIKO SETYO AL MAJID | D57: P
...

Sheet X-3
A14: DAFTAR HADIR
A15: TAHUN PELAJARAN 2025/ 2026
M17: Kelas | Q17: : X - 3
A18: KEGIATAN : ............................................................ | M18: Wali Kelas | Q18: : RISANTI DWI K., S. Pd.
A20: No Urut | B20: No Induk | C20: Nama | D20: L/P | E20: NILAI | U20: KETERANGAN
E23: 1 | F23: 2 | G23: 3 | H23: 4 | I23: 5 | J23: 6 | K23: 7 | L23: 8 | M23: 9 | N23: 10 | O23: 11 | P23: 12 | Q23: 13 | R23: 14 | S23: 15 | T23: 16
A24: 1 | B24: 12226 | C24: ANDHIKA YOSHIO VALDA | D24: L | E24: 1 | P24: 1 | T24: 1 | U24: 1
A25: 2 | B25: 12231 | C25: ANJOYAN R IMANUEL SAPULETTE | D25: L | P25: 1 | T25: 1 | U25: 1
A26: 3 | B26: 12234 | C26: ARETHA CATHERINE CRISNOVA MARPAUNG | D26: P | P26: 1 | T26: 1 | U26: 1
A27: 4 | B27: 12269 | C27: DAHAYUNA ALISIA RAHMA | D27: P | P27: 1 | T27: 1 | U27: 1
A28: 5 | B28: 12278 | C28: DWI BAGUS WICAKSONO | D28: L | P28: 1 | T28: 1 | U28: 1
A29: 6 | B29: 12286 | C29: FARIZ IMAN ADIPRATAMA | D29: L | P29: 1 | T29: 1 | U29: 1
A30: 7 | B30: 12287 | C30: FARIZ MAHENDRA SAKTI | D30: L | P30: 1 | T30: 1 | U30: 1
A31: 8 | B31: 12291 | C31: FEDYENKA YOFE SINE HARYADI | D31: L | P31: 1 | T31: 1 | U31: 1
A32: 9 | B32: 12307 | C32: HUGO COBAIN WELLEM VAN HOUTEN | D32: L | P32: 1 | T32: 1 | U32: 1
A33: 10 | B33: 12309 | C33: IMANUEL KRISTIAN SELA KAMODI | D33: L | P33: 1 | T33: 1 | U33: 1
A34: 11 | B34: 12318 | C34: JONATHAN IDO HALOMOAN SIRAIT | D34: L | P34: 1 | T34: 1 | U34: 1
A35: 12 | B35: 12319 | C35: JONATHAN IVANDER SANTOSA | D35: L | P35: 1 | T35: 1 | U35: 1
A36: 13 | B36: 12323 | C36: KANYA PRAJWALITA JYOSNAKARA | D36: P | P36: 1 | T36: 1 | U36: 1
... A43: 20 | B43: 12349 | C43: MINHAJUL QOWIM | D43: L | P43: 1 | T43: 1 | U43: 1
A44: 21 | B44: 12358 | C44: MUHAMMAD AL FAUZAN | D44: L
A45: 22 | B45: 12395 | C45: NAURA PUTRI MAHARANI | D45: P
A46: 23 | B46: 12400 | C46: NEWEN BESTIAN SIMAMORA | D46: L
A47: 24 | B47: 12401 | C47: NICO PRATAMA WIJAYA | D47: L
A48: 25 | B48: 12403 | C48: NUR WIDYA | D48: P
A49: 26 | B49: 12435 | C49: RIZKY AL BRIAN OKPARA | D49: L
A50: 27 | B50: 12439 | C50: SALMA JALANIDHI PRABOWO | D50: P
A51: 28 | B51: 12441 | C51: SAMUEL SURYA LABANTA BERUTU | D51: L
A52: 29 | B52: 12445 | C52: SATYA WIRADHIKA ZENERLYN | D52: L
A53: 30 | B53: 12450 | C53: SHERENA ZHAFIRA SRIBINTORO | D53: P
A54: 31 | B54: 12454 | C54: SYAHMIZAKY AYDIN PRADANA | D54: L | P54: 1 | T54: 1
A55: 32 | B55: 12455 | C55: SYARIFATUL JINAN | D55: P | U55: 1
A56: 33 | B56: 12462 | C56: VIKA APRILIA ZAHRA | D56: P
A57: 34 | B57: 12466 | C57: YOCELYN DWI MARTONO | D57: P
C58: JUMLAH SISWA LAKI-LAKI | D58: =COUNTIF(D24:D57,"L") -> 22
C59: JUMLAH SISWA PEREMPUAN | D59: =COUNTIF(D24:D57,"P") -> 12
C60: JUMLAH KESELURUHAN | D60: =SUM(D58:D59) -> 34

Sheet X-4
A14: DAFTAR HADIR
A15: TAHUN PELAJARAN 2025/ 2026
M17: Kelas | Q17: : X - 4
A18: KEGIATAN : ........................................................... | M18: Wali Kelas | Q18: : SATYO NUGROHO, S. Kom.
A20: No Urut | B20: No Induk | C20: Nama | D20: L/P | E20: NILAI | U20: KETERANGAN
E23: 1 | F23: 2 | G23: 3 | H23: 4 | I23: 5 | J23: 6 | K23: 7 | L23: 8 | M23: 9 | N23: 10 | O23: 11 | P23: 12 | Q23: 13 | R23: 14 | S23: 15 | T23: 16
A24: 1 | B24: 12207 | C24: ABIMANYU GUSTYA TAUFANO | D24: L | E24: 1 | P24: 1 | T24: 1 | U24: 1
A25: 2 | B25: 12214 | C25: AISYAH MAULIDA TSANIA | D25: P | P25: 1 | T25: 1 | U25: 1
A26: 3 | B26: 12221 | C26: ALVANO WIRA ARVIANTO | D26: L | P26: 1 | T26: 1 | U26: 1
A27: 4 | B27: 12224 | C27: ALYA PUTRI LESTARI | D27: P | P27: 1 | T27: 1 | U27: 1
A28: 5 | B28: 12229 | C28: ANDREAS KENZIE RADITHYA PUTRA | D28: L | P28: 1 | T28: 1 | U28: 1
A29: 6 | B29: 12232 | C29: ANNISA DINDA SUFIA | D29: P | P29: 1 | T29: 1 | U29: 1
A30: 7 | B30: 12252 | C30: AZMI NAFIAH ZAHRAH | D30: P | P30: 1 | T30: 1 | U30: 1
A31: 8 | B31: 12260 | C31: BRAMASTIAN NARENDRA | D31: L | P31: 1 | T31: 1 | U31: 1
A32: 9 | B32: 12281 | C32: ERGIAN ANDHIKA PRASETYA | D32: L | P32: 1 | T32: 1 | U32: 1
A33: 10 | B33: 12297 | C33: GIEVALDO YUDHA PRATAMA | D33: L | P33: 1 | T33: 1 | U33: 1
A34: 11 | B34: 12300 | C34: HANIN AMALIA PRAYOGA | D34: P | P34: 1 | T34: 1 | U34: 1
A35: 12 | B35: 12305 | C35: HERALD PUTRA SETYAHADI | D35: L | P35: 1 | T35: 1 | U35: 1
A36: 13 | B36: 12308 | C36: I PUTU WIANANTA PUTRA | D36: L | P36: 1 | T36: 1 | U36: 1
... A44: 21 | B44: 12369 | C44: MUHAMMAD KENZIE ARYASATYA ARDHANI | D44: L | P44: 1 | T44: 1 | U44: 1
A45: 22 | B45: 12378 | C45: MUHAMMAD YUSUF MULYANA | D45: L | U45: 1
A46: 23 | B46: 12381 | C46: NABILA CINTIA DEWI | D46: P
A47: 24 | B47: 12392 | C47: NAUFAL MAULANA | D47: L
A48: 25 | B48: 12397 | C48: NAYAKA PUTRA AZMI NUGROHO | D48: L
A49: 26 | B49: 12398 | C49: NAYLA DWI RAMADHANI | D49: P
A50: 27 | B50: 12399 | C50: NEVIRA DWININGTYAS | D50: P
A51: 28 | B51: 12416 | C51: RAFAEL ADHIKARI PRAMUDITO | D51: L
A52: 29 | B52: 12422 | C52: RASYA AHMAD RAMADHAN | D52: L | P52: 1 | T52: 1
A53: 30 | B53: 12434 | C53: RIZALDY ADITYA SEPTRIAN | D53: L
A54: 31 | B54: 12444 | C54: SATYA ANUGERAH | D54: L
A55: 32 | B55: 12461 | C55: VANEZA DEWI AYU NINGTYAS | D55: P
A56: 33 | B56: 12470 | C56: ZIDHA NURUL LAILY | D56: P
A57: 34 | B57: 12472 | C57: ZUDECA REVANDER ANDREA PRATAMA | D57: L | U57: 1
C58: JUMLAH SISWA LAKI-LAKI | D58: =COUNTIF(D24:D57,"L") -> 22
C59: JUMLAH SISWA PEREMPUAN | D59: =COUNTIF(D24:D57,"P") -> 12
C60: JUMLAH KESELURUHAN | D60: =SUM(D58:D59) -> 34
C61: JML

Sheet X-5
A14: DAFTAR HADIR
A15: TAHUN PELAJARAN 2025/ 2026
L17: Kelas | P17: : X - 5
A18: KEGIATAN : ................................................................ | L18: Wali Kelas | P18: : ZAKARIA RAMADHAN, S. Pd.
A20: No Urut | B20: No Induk | C20: Nama | D20: L/P | E20: NILAI | U20: KETERANGAN
E23: 1 | F23: 2 | G23: 3 | H23: 4 | I23: 5 | J23: 6 | K23: 7 | L23: 8 | M23: 9 | N23: 10 | O23: 11 | P23: 12 | Q23: 13 | R23: 14 | S23: 15 | T23: 16
A24: 1 | B24: 12208 | C24: ADELIO ALVARO PUTRA YURIMA | D24: L | E24: 1 | P24: 1 | T24: 1 | U24: 1
A25: 2 | B25: 12210 | C25: AFILZA MUKMIN | D25: P | P25: 1 | T25: 1 | U25: 1
A26: 3 | B26: 12219 | C26: ALIYA PUTRI CIPTA NAIRA | D26: P | P26: 1 | T26: 1 | U26: 1
A27: 4 | B27: 12235 | C27: ARGA SYAPUTRA BURSOKPATI | D27: L | P27: 1 | T27: 1 | U27: 1
A28: 5 | B28: 12236 | C28: ARGANI ATHALLAH BISMA | D28: L | P28: 1 | T28: 1 | U28: 1
A29: 6 | B29: 12246 | C29: AUFA DE RADITYA AHMAD AL GHAZI | D29: L | P29: 1 | T29: 1 | U29: 1
A30: 7 | B30: 12248 | C30: AULIA ZAHRA SALSABILA | D30: P | P30: 1 | T30: 1 | U30: 1
A31: 8 | B31: 12251 | C31: AZKA AURELYA ROHANDI | D31: P | P31: 1 | T31: 1 | U31: 1
A32: 9 | B32: 12263 | C32: CAESAR LEONARDO PRASTOWO | D32: L | P32: 1 | T32: 1 | U32: 1
A33: 10 | B33: 12264 | C33: CALISTHA ZIVA KURNIA | D33: P | P33: 1 | T33: 1 | U33: 1
A34: 11 | B34: 12276 | C34: DIEGO RASHAFA APRILIO | D34: L | P34: 1 | T34: 1 | U34: 1
A35: 12 | B35: 12280 | C35: ELYANIDEWI LESTARI | D35: P | P35: 1 | T35: 1 | U35: 1
A36: 13 | B36: 12284 | C36: FAKHRI RIZKI RAMDANI | D36: L | P36: 1 | T36: 1 | U36: 1
... A43: 20 | B43: 12320 | C43: JOSH PAYAMAN PRASETYA SIBURIAN | D43: L | P43: 1 | T43: 1 | U43: 1
A44: 21 | B44: 12326 | C44: KENNETH SHANE MARVEL WUWUNG | D44: L | U44: 1
A45: 22 | B45: 12330 | C45: KHAIRA SHAFIYA RAHMA ZAHRANI | D45: P | U45: 1
A46: 23 | B46: 12335 | C46: LASKAR ANUNG WIDAGDO | D46: L
A47: 24 | B47: 12346 | C47: MAULIDA FEBRIANA LUQMAN | D47: P
A48: 25 | B48: 12354 | C48: MOHAMMAD FAULLANA RAMADHANI | D48: L
A49: 26 | B49: 12365 | C49: MUHAMMAD GANESHA WISNU MURTI | D49: L
A50: 27 | B50: 12371 | C50: MUHAMMAD NAURA FEBRIAN SAIFULLAH | D50: L
A51: 28 | B51: 12384 | C51: NADIA NUR RAHMAN | D51: P
A52: 29 | B52: 12402 | C52: NOVA AZZAHRA QUEEN | D52: P
A53: 30 | B53: 12418 | C53: RAFI PRASETYO ALWISYAHPUTRA | D53: L
A54: 31 | B54: 12437 | C54: RIZKYAWAN HARIBU | D54: L
A55: 32 | B55: 12442 | C55: SANDRIO NATHANAEL PUTRA HERLAMBANG | D55: L | P55: 1 | T55: 1
A56: 33 | B56: 12448 | C56: SHAVIRA ADELLIA PUTRI | D56: P
C57: JUMLAH SISWA LAKI-LAKI | D57: =COUNTIF(D24:D56,"L") -> 21
C58: JUMLAH SISWA PEREMPUAN | D58: =COUNTIF(D24:D56,"P") -> 12
C59: JUMLAH KESELURUHAN | D59: =SUM(D57:D58) -> 33
C60: JML
A65: 31 | B65: 12429 | C65: REWALDIN FAHMI ANDHIKO | D65: L

Sheet X-6
A14: DAFTAR HADIR
A15: TAHUN PELAJARAN 2025/ 2026
L17: Kelas | P17: : X - 6
A18: KEGIATAN : ................................................................. | L18: Wali Kelas | P18: : HAJARUNI'AM H. A., S. Pd. I
A20: No Urut | B20: No Induk | C20: Nama | D20: L/P | E20: NILAI | U20: KETERANGAN
E23: 1 | F23: 2 | G23: 3 | H23: 4 | I23: 5 | J23: 6 | K23: 7 | L23: 8 | M23: 9 | N23: 10 | O23: 11 | P23: 12 | Q23: 13 | R23: 14 | S23: 15 | T23: 16
A24: 1 | B24: 12230 | C24: ANGGIE AULIA RAHMA | D24: P | E24: 1 | P24: 1 | T24: 1 | U24: 1
A25: 2 | B25: 12240 | C25: ARRAYHAN SYAMNAUFAL DAVINPUTRA | D25: L | P25: 1 | T25: 1 | U25: 1
A26: 3 | B26: 12241 | C26: ARSAWEDA PANDUNEGARA | D26: L | P26: 1 | T26: 1 | U26: 1
A27: 4 | B27: 12249 | C27: AULYA JAVIER PUTRANTI | D27: P | P27: 1 | T27: 1 | U27: 1
A28: 5 | B28: 12259 | C28: BIMA DWI SAPUTRA | D28: L | P28: 1 | T28: 1 | U28: 1
A29: 6 | B29: 12265 | C29: CEFIN SETYO ADJIE CHENO | D29: L | P29: 1 | T29: 1 | U29: 1
A30: 7 | B30: 12270 | C30: DAMIA AJLA BAKHREISYI | D30: P | P30: 1 | T30: 1 | U30: 1
A31: 8 | B31: 12274 | C31: DEWI WULANDARI PUTRI GIYARSO | D31: P | P31: 1 | T31: 1 | U31: 1
A32: 9 | B32: 12285 | C32: FAREL DEVANO PUTRA AFFANDI | D32: L | P32: 1 | T32: 1 | U32: 1
A33: 10 | B33: 12288 | C33: FATHAN AR ROYYAN | D33: L | P33: 1 | T33: 1 | U33: 1
A34: 11 | B34: 12294 | C34: FIRNANDA CHARISTANIA | D34: P | P34: 1 | T34: 1 | U34: 1
A35: 12 | B35: 12295 | C35: GADING GUMILANG | D35: L | P35: 1 | T35: 1 | U35: 1
A36: 13 | B36: 12314 | C36: JAYA MUSYAFFA SURYA SUDRAJAT | D36: L | P36: 1 | T36: 1 | U36: 1
... A41: 18 | B41: 12355 | C41: MUHAMMAD ABYASA ALVARO FARREL | D41: L | P41: 1 | T41: 1 | U41: 1
A42: 19 | B42: 12372 | C42: MUHAMMAD QUERREL ARAY AT TAQQI | D42: L
A43: 20 | B43: 12374 | C43: MUHAMMAD RAFI DANISWARA IRWAN | D43: L
A44: 21 | B44: 12386 | C44: NAHDAH ANINDYA IRAWAN | D44: P
A45: 22 | B45: 12394 | C45: NAURA AZIRWA AYUNDA TRIXIE | D45: P
A46: 23 | B46: 12406 | C46: OKTRIAN WIRA PRANATA | D46: L
A47: 24 | B47: 12409 | C47: PUTRI RISKIYANI AMBAR SARI | D47: P
A48: 25 | B48: 12411 | C48: QUEEN AZ-ZAHRA REPPY RACHMANISSA | D48: P
A49: 26 | B49: 12414 | C49: RADYA DIPA NUSANTARA | D49: L
A50: 27 | B50: 12419 | C50: RAHMAT RADIX SADANA | D50: L
A51: 28 | B51: 12428 | C51: REVANO DAVA SYAHREZA | D51: L
A52: 29 | B52: 12430 | C52: REYZA NUR ALAMSYAH | D52: L
A53: 30 | B53: 12432 | C53: RIO NAZRIL ERMIANSYAH | D53: L
... A55: 32 | B55: 12449 | C55: SHEFIRA INDAH WIRATRI | D55: P
A56: 33 | B56: 12458 | C56: TEGAR ARYO WIBOWO | D56: L | P56: 1 | T56: 1
A57: 34 | B57: 12468 | C57: ZIDAN FADHIL ADINATA | D57: L
C58: JUMLAH SISWA LAKI-LAKI | D58: =COUNTIF(D24:D57,"L") -> 22
C59: JUMLAH SISWA PEREMPUAN | D59: =COUNTIF(D24:D57,"P") -> 12
C60: JUMLAH KESELURUHAN | D60: =SUM(D58:D59) -> 34
C61: JML

Sheet X-7
A14: DAFTAR HADIR
A15: TAHUN PELAJARAN 2025/ 2026
N17: Kelas | R17: : X - 7
A18: KEGIATAN : ................................................................ | N18: Wali Kelas | R18: : NANIK FEBRI A., S. Pd.
A20: No Urut | B20: No Induk | C20: Nama | D20: L/P | E20: NILAI | U20: KETERANGAN
E23: 1 | F23: 2 | G23: 3 | H23: 4 | I23: 5 | J23: 6 | K23: 7 | L23: 8 | M23: 9 | N23: 10 | O23: 11 | P23: 12 | Q23: 13 | R23: 14 | S23: 15 | T23: 16
A24: 1 | B24: 12212 | C24: AHNAF IKHWAN MA'RUFI | D24: L | E24: 1 | P24: 1 | T24: 1 | U24: 1
A25: 2 | B25: 12213 | C25: AISYAH ALIFAH | D25: P | P25: 1 | T25: 1 | U25: 1
A26: 3 | B26: 12215 | C26: ALFANSYAH PANJI TRISULA | D26: L | P26: 1 | T26: 1 | U26: 1
A27: 4 | B27: 12218 | C27: ALIEF ANANTA AL RAFFI JULIANTO | D27: L | P27: 1 | T27: 1 | U27: 1
A28: 5 | B28: 12228 | C28: ANDI MUH FARID ALVARO SAYURI | D28: L | P28: 1 | T28: 1 | U28: 1
A29: 6 | B29: 12253 | C29: BAGAS ZAKI PRIONO | D29: L | P29: 1 | T29: 1 | U29: 1
A30: 7 | B30: 12254 | C30: BAGUS FIRMAN WIJAYA KUSUMA | D30: L | P30: 1 | T30: 1 | U30: 1
A31: 8 | B31: 12258 | C31: BILAL RAMADAN ASSAHRIF | D31: L | P31: 1 | T31: 1 | U31: 1
A32: 9 | B32: 12267 | C32: CHELSEA NAMIRA AZZAHRA | D32: P | P32: 1 | T32: 1 | U32: 1
A33: 10 | B33: 12271 | C33: DAVID IRWANSYAH | D33: L | P33: 1 | T33: 1 | U33: 1
A34: 11 | B34: 12279 | C34: ELMIRA LOUISA TARA | D34: P | P34: 1 | T34: 1 | U34: 1
A35: 12 | B35: 12283 | C35: FADILILLAH ACHMAD AZZAM | D35: L | P35: 1 | T35: 1 | U35: 1
A36: 13 | B36: 12303 | C36: HARDIAN ZAHFRAN BIMANTARA | D36: L | P36: 1 | T36: 1 | U36: 1
... A40: 17 | B40: 12366 | C40: MUHAMMAD HAIKAL HIBATULLAH | D40: L | P40: 1 | T40: 1 | U40: 1
A41: 18 | B41: 12370 | C41: MUHAMMAD NAUFAL RAJENDRA EKA WIDYADHANA | D41: L | P41: 1 | T41: 1
A42: 19 | B42: 12376 | C42: MUHAMMAD RIFQY HIDAYATULLOH | D42: L | P42: 1 | T42: 1
A43: 20 | B43: 12377 | C43: MUHAMMAD YUSUF IBRAHIM HERMAWAN | D43: L
A44: 21 | B44: 12388 | C44: NAMARIQ ZANZABILA FARADISA | D44: P
A45: 22 | B45: 12389 | C45: NATASYA NUR OKTAVIANA | D45: P
A46: 23 | B46: 12391 | C46: NAUFAL FATHIR ARKAN | D46: L
A47: 24 | B47: 12404 | C47: NURHALIZA FEVRIDA AYU PRASOJO | D47: P
A48: 25 | B48: 12413 | C48: RADITYA DZAKY PUTRA PRAJA | D48: L
A49: 26 | B49: 12421 | C49: RAKHA PUTRA DIRGANTARA | D49: L
A50: 27 | B50: 12425 | C50: RASYHA RAJENDRA SURYA BRAHMANA | D50: L
A51: 28 | B51: 12443 | C51: SASI KIRANA | D51: P
A52: 29 | B52: 12446 | C52: SEKAR CITRA ALOKA | D52: P
A53: 30 | B53: 12452 | C53: SHERRIN ARIESANTY MASFUFAH | D53: P
A54: 31 | B54: 12464 | C54: WIGAR LAZUARDI NUSANTARA | D54: L
C55: JUMLAH SISWA LAKI-LAKI | D55: =COUNTIF(D24:D54,"L") -> 21
C56: JUMLAH SISWA PEREMPUAN | D56: =COUNTIF(D24:D54,"P") -> 10
C57: JUMLAH KESELURUHAN | D57: =SUM(D55:D56) -> 31

Sheet X-8
A14: DAFTAR HADIR
A15: TAHUN PELAJARAN 2025/ 2026
M17: Kelas | Q17: : X - 8
A18: KEGIATAN : .................................................................. | M18: Wali Kelas | Q18: : CHAMALIA ARDHANA R., S. Pd.
A20: No Urut | B20: No Induk | C20: Nama | E20: L/P | F20: NILAI | V20: KETERANGAN
F23: 1 | G23: 2 | H23: 3 | I23: 4 | J23: 5 | K23: 6 | L23: 7 | M23: 8 | N23: 9 | O23: 10 | P23: 11 | Q23: 12 | R23: 13 | S23: 14 | T23: 15 | U23: 16
A24: 1 | B24: 12211 | C24: AHMAD ZAKY AL KAMIL | E24: L | F24: 1 | Q24: 1 | U24: 1 | V24: 1
A25: 2 | B25: 12216 | C25: ALFARA IZDIHAR ABADI | E25: L | Q25: 1 | U25: 1 | V25: 1
A26: 3 | B26: 12220 | C26: ALMIRA RAEHANA ISLAMY YARKHAM | E26: P | Q26: 1 | U26: 1 | V26: 1
A27: 4 | B27: 12225 | C27: ANDHIKA FAIZ HERLAMBANG | E27: L | Q27: 1 | U27: 1 | V27: 1
A28: 5 | B28: 12227 | C28: ANDI MUH FACHRY ADELIO SAYURI | E28: L | Q28: 1 | U28: 1 | V28: 1
A29: 6 | B29: 12233 | C29: ARDHA GINANJAR PRAYOGO | E29: L | Q29: 1 | U29: 1 | V29: 1
A30: 7 | B30: 12238 | C30: ARKA RIEZKY SOFYAN | E30: L | Q30: 1 | U30: 1 | V30: 1
A31: 8 | B31: 12243 | C31: ARYA PUTRA ALFARIZKI | E31: L | Q31: 1 | U31: 1 | V31: 1
A32: 9 | B32: 12247 | C32: AULIA AYU ANGGI PUTRI PRATIWI | E32: P | Q32: 1 | U32: 1 | V32: 1
A33: 10 | B33: 12250 | C33: AZIZ BAGUS PRIANTAMA | E33: L | Q33: 1 | U33: 1 | V33: 1
A34: 11 | B34: 12262 | C34: BUSHIDO AJIE SAPUTRA | E34: L | Q34: 1 | U34: 1 | V34: 1
A35: 12 | B35: 12273 | C35: DE PALESTINE DMAR | E35: P
A36: 13 | B36: 12277 | C36: DIFO AKBAR SYAH | E36: L
A37: 14 | B37: 12289 | C37: FATTA NURNABIL MUSIN | E37: L
A38: 15 | B38: 12293 | C38: FERDIAN YOGI PRIYANANTA | E38: L
A39: 16 | B39: 12306 | C39: HISSY FILOSOFI PANCA | E39: L
A40: 17 | B40: 12340 | C40: MAGENTA BIMANTARA PUTRA | E40: L
A41: 18 | B41: 12348 | C41: MIA SAFINA RAHMADANI | E41: P | Q41: 1 | U41: 1 | V41: 1
A42: 19 | B42: 12359 | C42: MUHAMMAD ARGYA IMHIL MUHAIJID | E42: L | Q42: 1 | U42: 1 | V42: 1
A43: 20 | B43: 12379 | C43: MUHAMMAD ZHAFIR AL FAYYADH ARDYANSYAH | E43: L | Q43: 1 | U43: 1 | V43: 1
A44: 21 | B44: 12380 | C44: MUKHAMMAD KRISNA DJANURI | E44: L | Q44: 1 | U44: 1 | V44: 1
A45: 22 | B45: 12382 | C45: NABILA RATNA JULIANA | E45: P
A46: 23 | B46: 12387 | C46: NAJLA AZRINE MAGHFIROH | E46: P | Q46: 1 | U46: 1 | V46: 1
A47: 24 | B47: 12396 | C47: NAVANO PUTRA KRISTYAWAN | E47: L | Q47: 1 | U47: 1 | V47: 1
A48: 25 | B48: 12405 | C48: OKKY SAKTI HERINA PUTRI | E48: P
A49: 26 | B49: 12407 | C49: PUTRI DIAN AFIFAH | E49: P
A50: 27 | B50: 12415 | C50: RAFA DWI ANUGERAH IMRON | E50: L
A51: 28 | B51: 12420 | C51: RAIHAN AFIF MUHAJIR | E51: L
A52: 29 | B52: 12423 | C52: RASYA DAMAR PANULUH | E52: L
A53: 30 | B53: 12456 | C53: SYIFA AULIA ZAHRA | E53: P
A54: 31 | B54: 12467 | C54: YUDHA BRAMANTYO | E54: L
C55: JUMLAH SISWA LAKI-LAKI | E55: =COUNTIF(E24:E54,"L") -> 22 | S55: 1 | V55: 1
C56: JUMLAH SISWA PEREMPUAN | E56: =COUNTIF(E24:E54,"P") -> 9 | S56: 1 | V56: 1
C57: JUMLAH KESELURUHAN | E57: =SUM(E55:E56) -> 31

Sheet OLAH SBSENSI 2025
A1: No Urut | B1: No Induk | C1: Nama | D1: L/P | E1: KELAS
A2: 1 | B2: 12206 | C2: ABID LUHUNG FITRA WIYONO | D2: L | E2: X-1
A3: 2 | B3: 12217 | C3: ALGIS QIANDRA YUDHA PRATAMA | D3: L | E3: X-1
A4: 3 | B4: 12222 | C4: ALVIAN RADITYA PRATAMA | D4: L | E4: X-1
A5: 4 | B5: 12242 | C5: ARSENDI ZIKRI UTOMO PUTRA | D5: L | E5: X-1
A6: 5 | B6: 12245 | C6: ASKA FATAH FEDORA ILAHI | D6: L | E6: X-1
A7: 6 | B7: 12255 | C7: BAIQ NINDI REGINA PUTRI | D7: P | E7: X-1
A8: 7 | B8: 12256 | C8: BERYL AFFAN AFLAHURROJI | D8: L | E8: X-1
A9: 8 | B9: 12261 | C9: BRILIAN RAFA RAMADAN | D9: L | E9: X-1
A10: 9 | B10: 12266 | C10: CHANTIKA INTANIA NURMAWATI BASKORO | D10: P | E10: X-1
A11: 10 | B11: 12268 | C11: DAFFA RAQILLA SUGIONO | D11: L | E11: X-1
A12: 11 | B12: 12272 | C12: DAVID MAULANA CHAMID | D12: L | E12: X-1
A13: 12 | B13: 12282 | C13: FADHIL AFFANDI FAYYADH | D13: L | E13: X-1
... A268: 31 | B268: 12467 | C268: YUDHA BRAMANTYO | D268: L | E268: X-8

Sheet REKAP
B1: L | C1: P
A2: X-1 | B2: ='X-1'!D57 -> 22 | C2: ='X-1'!D58 -> 11 | D2: ='X-1'!A56 -> 33
A3: X-2 | B3: ='X-2'!D58 -> 22 | C3: ='X-2'!D59 -> 12 | D3: ='X-2'!A57 -> 34
A4: X-3 | B4: ='X-3'!D58 -> 22 | C4: ='X-3'!D59 -> 12 | D4: ='X-3'!A57 -> 34
A5: X-4 | B5: ='X-4'!D58 -> 22 | C5: ='X-4'!D59 -> 12 | D5: ='X-4'!A57 -> 34
A6: X-5 | B6: ='X-5'!D57 -> 21 | C6: ='X-5'!D58 -> 12 | D6: ='X-5'!A56 -> 33
A7: X-6 | B7: ='X-6'!D58 -> 22 | C7: ='X-6'!D59 -> 12 | D7: ='X-6'!A57 -> 34
A8: X-7 | B8: ='X-7'!D55 -> 21 | C8: ='X-7'!D56 -> 10 | D8: ='X-7'!A54 -> 31
A9: X-8 | B9: ='X-8'!E55 -> 22 | C9: ='X-8'!E56 -> 9 | D9: ='X-8'!A54 -> 31
D11: =SUM(D2:D10) -> 264

Sheet Sheet1
A1: NO | B1: NAMA | C1: L/P | D1: AGAMA | E1: KELAS
A3: =A2+1 -> 1 | B3: ABID LUHUNG FITRA WIYONO | C3: L | D3: ISLAM | E3: X-1
A4: 1 | B4: ABIMANYU GUSTYA TAUFANO | C4: L | D4: ISLAM | E4: X-4
A5: 1 | B5: ADELIO ALVARO PUTRA YURIMA | C5: L | D5: ISLAM | E5: X-5
A6: 1 | B6: ADIYAT TAUFANI PUTRA GHANIAN | C6: L | D6: ISLAM | E6: X-2
A7: =A6+1 -> 2 | B7: AFILZA MUKMIN | C7: P | D7: ISLAM | E7: X-5
A8: 1 | B8: AHMAD ZAKY AL KAMIL | C8: L | D8: ISLAM | E8: X-8
A9: 1 | B9: AHNAF IKHWAN MA'RUFI | C9: L | D9: ISLAM | E9: X-7
A10: =A9+1 -> 2 | B10: AISYAH ALIFAH | C10: P | D10: ISLAM | E10: X-7
A11: =A10+1 -> 3 | B11: AISYAH MAULIDA TSANIA | C11: P | D11: ISLAM | E11: X-4
A12: =A11+1 -> 4 | B12: ALFANSYAH PANJI TRISULA | C12: L | D12: ISLAM | E12: X-7
A13: =A12+1 -> 5 | B13: ALFARA IZDIHAR ABADI | C13: L | D13: ISLAM | E13: X-8
A14: =A13+1 -> 6 | B14: ALGIS QIANDRA YUDHA PRATAMA | C14: L | D14: ISLAM | E14: X-1
A15: =A14+1 -> 7 | B15: ALIEF ANANTA AL RAFFI JULIANTO | C15: L | D15: ISLAM | E15: X-7
A16: =A15+1 -> 8 | B16: ALIYA PUTRI CIPTA NAIRA | C16: P | D16: ISLAM | E16: X-5
A17: =A16+1 -> 9 | B17: ALMIRA RAEHANA ISLAMY YARKHAM | C17: P | D17: ISLAM | E17: X-8
A18: =A17+1 -> 10 | B18: ALVANO WIRA ARVIANTO | C18: L | D18: ISLAM | E18: X-4
A19: =A18+1 -> 11 | B19: ALVIAN RADITYA PRATAMA | C19: L | D19: ISLAM | E19: X-1
A20: =A19+1 -> 12 | B20: ALVINO SATRIA PUTRA JATMIKO | C20: L | D20: ISLAM | E20: X-2
A21: =A20+1 -> 13 | B21: ALYA PUTRI LESTARI | C21: P | D21: ISLAM | E21: X-4
A22: =A21+1 -> 14 | B22: ANDHIKA FAIZ HERLAMBANG | C22: L | D22: ISLAM | E22: X-8
A23: 1 | B23: ANDHIKA YOSHIO VALDA | C23: L | D23: ISLAM | E23: X-3
A24: =A23+1 -> 2 | B24: ANDI MUH FACHRY ADELIO SAYURI | C24: L | D24: ISLAM | E24: X-8
A25: =A24+1 -> 3 | B25: ANDI MUH FARID ALVARO SAYURI | C25: L | D25: ISLAM | E25: X-7
A26: =A25+1 -> 4 | B26: ANDREAS KENZIE RADITHYA PUTRA | C26: L | D26: KATOLIK | E26: X-4
A27: 1 | B27: ANGGIE AULIA RAHMA | C27: P | D27: ISLAM | E27: X-6
A28: =A27+1 -> 2 | B28: ANJOYAN R IMANUEL SAPULETTE | C28: L | D28: KRISTEN | E28: X-3
A29: =A28+1 -> 3 | B29: ANNISA DINDA SUFIA | C29: P | D29: ISLAM | E29: X-4
A30: =A29+1 -> 4 | B30: ARDHA GINANJAR PRAYOGO | C30: L | D30: ISLAM | E30: X-8
A31: =A30+1 -> 5 | B31: ARETHA CATHERINE CRISNOVA MARPAUNG | C31: P | D31: KRISTEN | E31: X-3
A32: =A31+1 -> 6 | B32: ARGA SYAPUTRA BURSOKPATI | C32: L | D32: KRISTEN | E32: X-5
A33: =A32+1 -> 7 | B33: ARGANI ATHALLAH BISMA | C33: L | D33: ISLAM | E33: X-5
A34: =A33+1 -> 8 | B34: ARIA FALIHA ABYDZA | C34: L | D34: ISLAM | E34: X-2
A35: =A34+1 -> 9 | B35: ARKA RIEZKY SOFYAN | C35: L | D35: ISLAM | E35: X-8
A36: =A35+1 -> 10 | B36: ARRAFI FAJRI MUHARRAM | C36: L | D36: ISLAM | E36: X-2
A37: =A36+1 -> 11 | B37: ARRAYHAN SYAMNAUFAL DAVINPUTRA | C37: L | D37: ISLAM | E37: X-6
A38: =A37+1 -> 12 | B38: ARSAWEDA PANDUNEGARA | C38: L | D38: ISLAM | E38: X-6
A39: =A38+1 -> 13 | B39: ARSENDI ZIKRI UTOMO PUTRA | C39: L | D39: ISLAM | E39: X-1
... A269: =A268+1 -> 243 | B269: ZUDECA REVANDER ANDREA PRATAMA | C269: L | D269: ISLAM | E269: X-4
